TIMESTAMP >>> 2022-01-19 23:00:35.621414
(mysql.connector.errors.ProgrammingError) 1044 (42000): Access denied for user 'mefisher2'@'%' to database 'mefisher2$cccs' [SQL: "CREATE DATABASE mefisher2$cccs CHARACTER SET = 'utf8'"] (Background on this error at: http://sqlalche.me/e/f405)

TIMESTAMP >>> 2022-01-19 23:00:35.904761
(mysql.connector.errors.ProgrammingError) 1044 (42000): Access denied for user 'mefisher2'@'%' to database 'mefisher2$cccs' [SQL: "CREATE DATABASE mefisher2$cccs CHARACTER SET = 'utf8'"] (Background on this error at: http://sqlalche.me/e/f405)

TIMESTAMP >>> 2022-01-19 23:00:37.150947
(mysql.connector.errors.ProgrammingError) 1044 (42000): Access denied for user 'mefisher2'@'%' to database 'mefisher2$cccs' [SQL: "CREATE DATABASE mefisher2$cccs CHARACTER SET = 'utf8'"] (Background on this error at: http://sqlalche.me/e/f405)

TIMESTAMP >>> 2022-01-19 23:01:25.031539
(mysql.connector.errors.ProgrammingError) 1146 (42S02): Table 'mefisher2$cccs.Menu_data' doesn't exist [SQL: 'SELECT `Menu_data`.link AS `Menu_data_link`, `Menu_data`.name AS `Menu_data_name` \nFROM `Menu_data`'] (Background on this error at: http://sqlalche.me/e/f405)

TIMESTAMP >>> 2022-01-19 23:01:25.039155
(mysql.connector.errors.ProgrammingError) 1146 (42S02): Table 'mefisher2$cccs.Site_data' doesn't exist [SQL: 'SELECT `Site_data`.site_title AS `Site_data_site_title`, `Site_data`.site_logo AS `Site_data_site_logo`, `Site_data`.fav_icon AS `Site_data_fav_icon` \nFROM `Site_data`'] (Background on this error at: http://sqlalche.me/e/f405)

TIMESTAMP >>> 2022-01-19 23:01:30.760570
(mysql.connector.errors.ProgrammingError) 1146 (42S02): Table 'mefisher2$cccs.Menu_data' doesn't exist [SQL: 'SELECT `Menu_data`.link AS `Menu_data_link`, `Menu_data`.name AS `Menu_data_name` \nFROM `Menu_data`'] (Background on this error at: http://sqlalche.me/e/f405)

TIMESTAMP >>> 2022-01-19 23:01:30.771222
(mysql.connector.errors.ProgrammingError) 1146 (42S02): Table 'mefisher2$cccs.Site_data' doesn't exist [SQL: 'SELECT `Site_data`.site_title AS `Site_data_site_title`, `Site_data`.site_logo AS `Site_data_site_logo`, `Site_data`.fav_icon AS `Site_data_fav_icon` \nFROM `Site_data`'] (Background on this error at: http://sqlalche.me/e/f405)

TIMESTAMP >>> 2022-01-19 23:06:27.619115
tuple indices must be integers or slices, not str

TIMESTAMP >>> 2022-01-19 23:06:27.631320
tuple indices must be integers or slices, not str

TIMESTAMP >>> 2022-01-19 23:06:27.793510
tuple indices must be integers or slices, not str

TIMESTAMP >>> 2022-01-19 23:06:27.800008
tuple indices must be integers or slices, not str

TIMESTAMP >>> 2022-01-19 23:07:58.382623
tuple indices must be integers or slices, not str

TIMESTAMP >>> 2022-01-19 23:07:59.489308
tuple indices must be integers or slices, not str

TIMESTAMP >>> 2022-01-19 23:09:24.549688
tuple indices must be integers or slices, not str

TIMESTAMP >>> 2022-01-19 23:09:25.711014
tuple indices must be integers or slices, not str

TIMESTAMP >>> 2022-01-19 23:10:41.272212
tuple indices must be integers or slices, not str

TIMESTAMP >>> 2022-01-19 23:10:42.171145
tuple indices must be integers or slices, not str

TIMESTAMP >>> 2022-01-19 23:12:18.161504
tuple indices must be integers or slices, not str

TIMESTAMP >>> 2022-01-19 23:12:18.807706
tuple indices must be integers or slices, not str

TIMESTAMP >>> 2022-01-19 23:12:19.261811
tuple indices must be integers or slices, not str

TIMESTAMP >>> 2022-01-19 23:13:09.987034
tuple indices must be integers or slices, not str

TIMESTAMP >>> 2022-01-19 23:13:10.152510
tuple indices must be integers or slices, not str

TIMESTAMP >>> 2022-01-19 23:15:22.430885
tuple indices must be integers or slices, not str

TIMESTAMP >>> 2022-01-19 23:15:25.491362
tuple indices must be integers or slices, not str

TIMESTAMP >>> 2022-01-19 23:15:41.929251
tuple indices must be integers or slices, not str

TIMESTAMP >>> 2022-01-19 23:15:42.704644
tuple indices must be integers or slices, not str

TIMESTAMP >>> 2022-01-19 23:21:52.523482
tuple indices must be integers or slices, not str

TIMESTAMP >>> 2022-01-19 23:22:01.141201
tuple indices must be integers or slices, not str

TIMESTAMP >>> 2022-01-19 23:26:20.360597
tuple indices must be integers or slices, not str

TIMESTAMP >>> 2022-01-19 23:26:21.461216
tuple indices must be integers or slices, not str

TIMESTAMP >>> 2022-01-19 23:26:22.834521
tuple indices must be integers or slices, not str

TIMESTAMP >>> 2022-01-19 23:26:49.746459
tuple indices must be integers or slices, not str

TIMESTAMP >>> 2022-01-20 00:53:56.727073
'Announcement' object has no attribute '_asdict'

TIMESTAMP >>> 2022-01-20 00:54:01.405486
'Announcement' object has no attribute '_asdict'

TIMESTAMP >>> 2022-01-20 00:54:35.839622
'Announcement' object has no attribute '_asdict'

TIMESTAMP >>> 2022-01-20 00:54:55.084052
'Announcement' object has no attribute '_asdict'

TIMESTAMP >>> 2022-01-20 00:54:59.776532
'Announcement' object has no attribute '_asdict'

TIMESTAMP >>> 2022-01-20 00:55:11.699786
'Announcement' object has no attribute '_asdict'

TIMESTAMP >>> 2022-01-20 00:56:25.378439
'Announcement' object is not iterable

TIMESTAMP >>> 2022-01-20 00:56:30.256051
'Announcement' object is not iterable

TIMESTAMP >>> 2022-01-20 01:12:20.800543
(mysql.connector.errors.DataError) 1292 (22007): Incorrect datetime value: '' for column `cccs`.`announcement`.`event_time` at row 1
[SQL: INSERT INTO `Announcement` (message, event_time, create_time) VALUES (%(message)s, %(event_time)s, %(create_time)s)]
[parameters: {'message': '', 'event_time': '', 'create_time': datetime.datetime(2022, 1, 20, 1, 12, 20, 796172)}]
(Background on this error at: http://sqlalche.me/e/14/9h9h)

TIMESTAMP >>> 2022-01-20 01:26:08.141849
(mysql.connector.errors.DataError) 1292 (22007): Incorrect datetime value: '' for column `cccs`.`announcement`.`event_time` at row 1
[SQL: INSERT INTO `Announcement` (message, event_time, create_time) VALUES (%(message)s, %(event_time)s, %(create_time)s)]
[parameters: {'message': '', 'event_time': '', 'create_time': datetime.datetime(2022, 1, 20, 1, 26, 8, 138854)}]
(Background on this error at: http://sqlalche.me/e/14/9h9h)

TIMESTAMP >>> 2022-01-20 01:26:29.885586
(mysql.connector.errors.DataError) 1292 (22007): Incorrect datetime value: '' for column `cccs`.`announcement`.`event_time` at row 1
[SQL: INSERT INTO `Announcement` (message, event_time, create_time) VALUES (%(message)s, %(event_time)s, %(create_time)s)]
[parameters: {'message': '', 'event_time': '', 'create_time': datetime.datetime(2022, 1, 20, 1, 26, 29, 882700)}]
(Background on this error at: http://sqlalche.me/e/14/9h9h)

TIMESTAMP >>> 2022-01-20 01:36:16.112501
(mysql.connector.errors.DataError) 1292 (22007): Incorrect datetime value: '' for column `cccs`.`announcement`.`event_time` at row 1
[SQL: INSERT INTO `Announcement` (message, event_time, create_time) VALUES (%(message)s, %(event_time)s, %(create_time)s)]
[parameters: {'message': '', 'event_time': '', 'create_time': datetime.datetime(2022, 1, 20, 1, 36, 16, 110474)}]
(Background on this error at: http://sqlalche.me/e/14/9h9h)

TIMESTAMP >>> 2022-01-20 01:42:29.606256
(mysql.connector.errors.DataError) 1292 (22007): Incorrect datetime value: '' for column `cccs`.`announcement`.`event_time` at row 1
[SQL: INSERT INTO `Announcement` (message, event_time, create_time) VALUES (%(message)s, %(event_time)s, %(create_time)s)]
[parameters: {'message': 'testing event message', 'event_time': '', 'create_time': datetime.datetime(2022, 1, 20, 1, 42, 29, 603264)}]
(Background on this error at: http://sqlalche.me/e/14/9h9h)

TIMESTAMP >>> 2022-01-20 01:42:29.607261
This Session's transaction has been rolled back due to a previous exception during flush. To begin a new transaction with this Session, first issue Session.rollback(). Original exception was: (mysql.connector.errors.DataError) 1292 (22007): Incorrect datetime value: '' for column `cccs`.`announcement`.`event_time` at row 1
[SQL: INSERT INTO `Announcement` (message, event_time, create_time) VALUES (%(message)s, %(event_time)s, %(create_time)s)]
[parameters: {'message': 'testing event message', 'event_time': '', 'create_time': datetime.datetime(2022, 1, 20, 1, 42, 29, 603264)}]
(Background on this error at: http://sqlalche.me/e/14/9h9h) (Background on this error at: http://sqlalche.me/e/14/7s2a)

TIMESTAMP >>> 2022-01-20 03:01:20.341090
'str' object is not callable

TIMESTAMP >>> 2022-01-20 03:01:29.044253
'str' object is not callable

TIMESTAMP >>> 2022-01-20 03:01:37.656507
'str' object is not callable

TIMESTAMP >>> 2022-01-20 03:04:08.459261
'str' object is not callable

TIMESTAMP >>> 2022-01-20 03:04:56.495786
'str' object is not callable

TIMESTAMP >>> 2022-01-20 03:06:52.391441
'str' object is not callable

TIMESTAMP >>> 2022-01-20 03:07:48.099609
'<' not supported between instances of 'NoneType' and 'datetime.datetime'

